#VRML_SIM R2023b utf8

EXTERNPROTO "https://raw.githubusercontent.com/cyberbotics/webots/R2023b/projects/appearances/protos/OsbWood.proto"
EXTERNPROTO "https://raw.githubusercontent.com/cyberbotics/webots/R2023b/projects/objects/floors/protos/RectangleArena.proto"
EXTERNPROTO "https://raw.githubusercontent.com/cyberbotics/webots/R2023b/projects/objects/backgrounds/protos/TexturedBackground.proto"
EXTERNPROTO "https://raw.githubusercontent.com/cyberbotics/webots/R2023b/projects/objects/backgrounds/protos/TexturedBackgroundLight.proto"

WorldInfo {
  info [
    "In this example, the robot moves down a slope."
    "The altimeter is used to record the robots height."
  ]
  title "Altimeter"
  basicTimeStep 8
  contactProperties [
    ContactProperties {
      material2 "body"
      coulombFriction [
        0
      ]
      softCFM 0.1
    }
  ]
}
Viewpoint {
  orientation -0.2703891563395885 -0.569867878919129 0.7759770001167421 5.530059724846478
  position -1.3027938487843664 0.7322307263554658 0.9385386981410703
}
TexturedBackground {
}
TexturedBackgroundLight {
}
RectangleArena {
}
PointLight {
  attenuation 0 0 1
  intensity 0.6
  location 0.6 0 0
}
DEF SLOPE Solid {
  translation 0 0 0.15
  rotation 0 1 0 -0.4
  children [
    Shape {
      appearance OsbWood {
        textureTransform TextureTransform {
          scale 0.5 2
        }
      }
      geometry DEF BOX0 Box {
        size 0.8 0.2 0.02
      }
    }
  ]
  name "green box"
  boundingObject USE BOX0
}
Robot {
  translation -0.10088760947196745 1.7101959539550813e-05 0.11830771063897039
  rotation -0.2458300373646552 -1.1605610189059845e-06 0.9693129488085598 3.1415489193220316
  children [
    DistanceSensor {
      translation 0.024 -0.02 0.063
      rotation 0 0 1 -0.500795
      children [
        DEF Sensor Transform {
        }
      ]
      name "DS1"
    }
    Altimeter {
    }
    Pose {
      translation 0 0 0.0415
      children [
        Shape {
          appearance PBRAppearance {
            baseColor 0.0820075 0.364731 0.8
            roughness 1
            metalness 0
          }
          geometry DEF BODY Cylinder {
            height 0.08
            radius 0.045
          }
        }
      ]
    }
    HingeJoint {
      jointParameters HingeJointParameters {
        position 16.72000241586934
        axis 0 1 0
        anchor 0 0 0.025
      }
      device [
        RotationalMotor {
          name "left wheel motor"
          consumptionFactor 70
        }
        PositionSensor {
          name "left wheel sensor"
        }
      ]
      endPoint Solid {
        translation 0 0.04499999999999978 0.025
        rotation -0.6929920009655449 0.6929920536857769 -0.19880669034552015 2.7490969420921902
        children [
          DEF WHEEL Pose {
            rotation 0.577656895078166 0.5771968951617173 -0.5771968951617173 -2.093935
            children [
              Shape {
                appearance PBRAppearance {
                  baseColor 1 0 0
                  roughness 1
                  metalness 0
                }
                geometry Cylinder {
                  height 0.01
                  radius 0.025
                }
              }
            ]
          }
        ]
        name "left wheel"
        boundingObject USE WHEEL
        physics DEF PHYSICS_WHEEL Physics {
          density -1
          mass 0.05
        }
        linearVelocity -5.278952861420545e-06 -2.193531996124491e-13 -2.2319059284647853e-06
        angularVelocity 9.433999598776911e-09 -1.0105484039926761e-10 -2.2286132809988578e-08
      }
    }
    HingeJoint {
      jointParameters HingeJointParameters {
        position 16.7200024053961
        axis 0 1 0
        anchor 0 0 0.025
      }
      device [
        RotationalMotor {
          name "right wheel motor"
          consumptionFactor 70
        }
        PositionSensor {
          name "right wheel sensor"
        }
      ]
      endPoint Solid {
        translation 0 -0.045 0.025
        rotation -0.6929920004244335 0.6929920531446657 -0.19880669411788635 2.749096934834318
        children [
          USE WHEEL
        ]
        boundingObject USE WHEEL
        physics USE PHYSICS_WHEEL
        linearVelocity -5.2769471010893915e-06 -3.1450247435634816e-13 -2.231056884500761e-06
        angularVelocity 9.434035418037117e-09 -1.0108302749876792e-10 -2.2286167166006148e-08
      }
    }
    DistanceSensor {
      translation 0.042 0.02 0.063
      rotation 0 0 -1 -0.499
      children [
        DEF Sensor Transform {
          rotation 0.577656895078166 0.5771968951617173 -0.5771968951617173 -2.09394
          children [
            Shape {
              appearance PBRAppearance {
                baseColor 0.97 0.98 0.025
                roughness 1
                metalness 0
              }
              geometry Cylinder {
                height 0.004
                radius 0.008
              }
            }
          ]
        }
      ]
      name "DS0"
      lookupTable [
        0 1024 0
        0.05 1024 0
      ]
      numberOfRays 2
    }
  ]
  name "MyBot"
  contactMaterial "body"
  boundingObject Pose {
    translation 0 0 0.0415
    rotation 0 0 1 -1.570796
    children [
      USE BODY
    ]
  }
  physics Physics {
    density -1
    mass 0.5
  }
  controller ""
  linearVelocity -5.277951445028067e-06 3.8131577730944767e-11 -2.2314821993489874e-06
  angularVelocity 9.434014604705015e-09 -1.0105465754128312e-10 -2.2286141496820876e-08
}
